Workbook

Sheet Summary
A1: Summary — Market Garden Bed Allocation
A2: perfect-competition engagement · marginal-analysis capability · see Solver tab to change the allocation
A4: Allocation (Solver optimum)
A5: Crop | B5: Beds | C5: Price/bed | D5: Fertilizer/bed | E5: Revenue
A6: Tomato | B6: =Calculations!$E$39 | C6: =Tomato_Price | D6: =Tomato_Fertilizer_Per_Bed | E6: =B6*C6
A7: Carrot | B7: =Calculations!$E$40 | C7: =Carrot_Price | D7: =Carrot_Fertilizer_Per_Bed | E7: =B7*C7
A8: Mesclun | B8: =Calculations!$E$41 | C8: =Mesclun_Price | D8: =Mesclun_Fertilizer_Per_Bed | E8: =B8*C8
A9: Total beds | B9: =SUM(B6:B8)
A11: Labor & Cost Summary
A12: Temp workers hired | D12: =Calculations!$E$42
A13: Total labor hours needed | D13: =Calculations!$E$46
A14: Revenue | D14: =Calculations!$E$50
A15: Fertilizer cost | D15: =Calculations!$E$51
A16: Labor cost (tiered) | D16: =Calculations!$E$49
A17: Total Contribution | D17: =Calculations!$E$52
A18: Fixed Cost | D18: =Fixed_Cost
A19: PROFIT | D19: =Calculations!$E$53
A21: Greedy P=MC Walk vs. Solver (spec §5/§9)
A22: Greedy walk beds — Tomato / Carrot / Mesclun | C22: =Calculations!$D$148 | D22: =Calculations!$E$148 | E22: =Calculations!$F$148
A23: Greedy walk PROFIT | D23: =Calculations!$D$152
A24: Delta vs. Solver PROFIT | D24: =Calculations!$D$153
A26: Hypothesis Verdict (spec §7/§9)
A27: Check 1 — Carrots > Mesclun beds? | D27: =Calculations!$E$66
A28: Check 5 — Swap test (Mesclun-1/Carrot+1) verdict | D28: =Calculations!$E$75
A29: Checks 2-4 require manual re-runs — see Notes tab.

Sheet Inputs
A1: Inputs — Market Garden Bed Allocation (v1.5)
A2: capabilities/marginal-analysis · perfect-competition engagement · edit only the yellow cells
A4: Category | B4: Named Range | C4: Value | D4: Unit
A5: Bed capacity | B5: Total_Beds | C5: 64 | D5: beds
B6: Tomato_Bed_Cap | C6: 20 | D6: beds
B7: Carrot_Bed_Cap | C7: 20 | D7: beds
B8: Mesclun_Bed_Cap | C8: 30 | D8: beds
A9: Season | B9: Season_Weeks | C9: 36 | D9: weeks
A10: Fixed costs | B10: Fixed_Cost | C10: 20000 | D10: $
A11: Labor pool | B11: Farmer_Season_Salary | C11: 50000 | D11: $/season
B12: Farmer_Implied_Wage | C12: =Farmer_Season_Salary/2/Own_Labor_Hours | D12: $/hr
B13: Own_Labor_Hours | C13: 720 | D13: hrs
B14: Temp_Worker_Max | C14: 4 | D14: workers
B15: Temp_Worker_Hours | C15: 1440 | D15: hrs/worker
B16: Temp_Worker_Flat_Cost | C16: 25000 | D16: $/worker
B17: Temp_Wage_Per_Hour | C17: =Temp_Worker_Flat_Cost/Temp_Worker_Hours | D17: $/hr
A18: Crop economics | B18: Tomato_Price | C18: 8800 | D18: $/bed
B19: Carrot_Price | C19: 2094 | D19: $/bed
B20: Mesclun_Price | C20: 2700 | D20: $/bed
B21: Tomato_Fertilizer_Per_Bed | C21: 880 | D21: $/bed
B22: Carrot_Fertilizer_Per_Bed | C22: 440 | D22: $/bed
B23: Mesclun_Fertilizer_Per_Bed | C23: 880 | D23: $/bed
B24: Tomato_Base_Labor_Hrs_Wk_Bed | C24: 2.5 | D24: hrs/wk/bed
B25: Carrot_Base_Labor_Hrs_Wk_Bed | C25: =C24/3 | D25: hrs/wk/bed
B26: Mesclun_Base_Labor_Hrs_Wk_Bed | C26: 1.25 | D26: hrs/wk/bed
B27: Tomato_Diminishing_Rate | C27: 0.1 | D27: %/bed
B28: Carrot_Diminishing_Rate | C28: 0.025 | D28: %/bed
B29: Mesclun_Diminishing_Rate | C29: 0.0125 | D29: %/bed

Sheet Calculations
A1: Calculations — Per-Crop Marginal Cost Curves (standalone)
A2: Standalone view: each crop's OWN cumulative hours determine which wage tier it's in (spec §5) -- first Own_Labor_Hours (720) of THAT CROP's hours are the expensive Farmer_Implied_Wage tier, rest are the cheaper Temp_Wage_Per_Hour tier. This is a sanity-check reference, not the joint answer (the Joint Allocation section below uses the real shared pool).
B3: Tomato | I3: Carrot | P3: Mesclun
B4: Bed # | C4: Marginal Hrs | D4: Cumulative Hrs | E4: Marg. Cost (standalone) | F4: Marg. Contribution | G4: Cumul. Contribution | H4: Still profitable? | I4: Bed # | J4: Marginal Hrs | K4: Cumulative Hrs | L4: Marg. Cost (standalone) | M4: Marg. Contribution | N4: Cumul. Contribution | O4: Still profitable? | P4: Bed # | Q4: Marginal Hrs | R4: Cumulative Hrs | S4: Marg. Cost (standalone) | T4: Marg. Contribution | U4: Cumul. Contribution | V4: Still profitable?
B5: =ROW()-4 | C5: =(B5*Tomato_Base_Labor_Hrs_Wk_Bed*Season_Weeks*(1+Tomato_Diminishing_Rate)^B5)-((B5-1)*Tomato_Base_Labor_Hrs_Wk_Bed*Season_Weeks*(1+Tomato_Diminishing_Rate)^(B5-1)) | D5: =SUM($C$5:C5) | E5: =MAX(0,MIN(D5,Own_Labor_Hours)-MIN((D5-C5),Own_Labor_Hours))*Farmer_Implied_Wage+(C5-MAX(0,MIN(D5,Own_Labor_Hours)-MIN((D5-C5),Own_Labor_Hours)))*Temp_Wage_Per_Hour+Tomato_Fertilizer_Per_Bed | F5: =Tomato_Price-E5 | G5: =SUM($F$5:F5) | H5: =AND(TRUE(),F5>=0) | I5: =ROW()-4 | J5: =(I5*Carrot_Base_Labor_Hrs_Wk_Bed*Season_Weeks*(1+Carrot_Diminishing_Rate)^I5)-((I5-1)*Carrot_Base_Labor_Hrs_Wk_Bed*Season_Weeks*(1+Carrot_Diminishing_Rate)^(I5-1)) | K5: =SUM($J$5:J5) | L5: =MAX(0,MIN(K5,Own_Labor_Hours)-MIN((K5-J5),Own_Labor_Hours))*Farmer_Implied_Wage+(J5-MAX(0,MIN(K5,Own_Labor_Hours)-MIN((K5-J5),Own_Labor_Hours)))*Temp_Wage_Per_Hour+Carrot_Fertilizer_Per_Bed | M5: =Carrot_Price-L5 | N5: =SUM($M$5:M5) | O5: =AND(TRUE(),M5>=0) | P5: =ROW()-4 | Q5: =(P5*Mesclun_Base_Labor_Hrs_Wk_Bed*Season_Weeks*(1+Mesclun_Diminishing_Rate)^P5)-((P5-1)*Mesclun_Base_Labor_Hrs_Wk_Bed*Season_Weeks*(1+Mesclun_Diminishing_Rate)^(P5-1)) | R5: =SUM($Q$5:Q5) | S5: =MAX(0,MIN(R5,Own_Labor_Hours)-MIN((R5-Q5),Own_Labor_Hours))*Farmer_Implied_Wage+(Q5-MAX(0,MIN(R5,Own_Labor_Hours)-MIN((R5-Q5),Own_Labor_Hours)))*Temp_Wage_Per_Hour+Mesclun_Fertilizer_Per_Bed | T5: =Mesclun_Price-S5 | U5: =SUM($T$5:T5) | V5: =AND(TRUE(),T5>=0)
B6: =ROW()-4 | C6: =(B6*Tomato_Base_Labor_Hrs_Wk_Bed*Season_Weeks*(1+Tomato_Diminishing_Rate)^B6)-((B6-1)*Tomato_Base_Labor_Hrs_Wk_Bed*Season_Weeks*(1+Tomato_Diminishing_Rate)^(B6-1)) | D6: =SUM($C$5:C6) | E6: =MAX(0,MIN(D6,Own_Labor_Hours)-MIN((D6-C6),Own_Labor_Hours))*Farmer_Implied_Wage+(C6-MAX(0,MIN(D6,Own_Labor_Hours)-MIN((D6-C6),Own_Labor_Hours)))*Temp_Wage_Per_Hour+Tomato_Fertilizer_Per_Bed | F6: =Tomato_Price-E6 | G6: =SUM($F$5:F6) | H6: =AND(H5,F6>=0) | I6: =ROW()-4 | J6: =(I6*Carrot_Base_Labor_Hrs_Wk_Bed*Season_Weeks*(1+Carrot_Diminishing_Rate)^I6)-((I6-1)*Carrot_Base_Labor_Hrs_Wk_Bed*Season_Weeks*(1+Carrot_Diminishing_Rate)^(I6-1)) | K6: =SUM($J$5:J6) | L6: =MAX(0,MIN(K6,Own_Labor_Hours)-MIN((K6-J6),Own_Labor_Hours))*Farmer_Implied_Wage+(J6-MAX(0,MIN(K6,Own_Labor_Hours)-MIN((K6-J6),Own_Labor_Hours)))*Temp_Wage_Per_Hour+Carrot_Fertilizer_Per_Bed | M6: =Carrot_Price-L6 | N6: =SUM($M$5:M6) | O6: =AND(O5,M6>=0) | P6: =ROW()-4 | Q6: =(P6*Mesclun_Base_Labor_Hrs_Wk_Bed*Season_Weeks*(1+Mesclun_Diminishing_Rate)^P6)-((P6-1)*Mesclun_Base_Labor_Hrs_Wk_Bed*Season_Weeks*(1+Mesclun_Diminishing_Rate)^(P6-1)) | R6: =SUM($Q$5:Q6) | S6: =MAX(0,MIN(R6,Own_Labor_Hours)-MIN((R6-Q6),Own_Labor_Hours))*Farmer_Implied_Wage+(Q6-MAX(0,MIN(R6,Own_Labor_Hours)-MIN((R6-Q6),Own_Labor_Hours)))*Temp_Wage_Per_Hour+Mesclun_Fertilizer_Per_Bed | T6: =Mesclun_Price-S6 | U6: =SUM($T$5:T6) | V6: =AND(V5,T6>=0)
B7: =ROW()-4 | C7: =(B7*Tomato_Base_Labor_Hrs_Wk_Bed*Season_Weeks*(1+Tomato_Diminishing_Rate)^B7)-((B7-1)*Tomato_Base_Labor_Hrs_Wk_Bed*Season_Weeks*(1+Tomato_Diminishing_Rate)^(B7-1)) | D7: =SUM($C$5:C7) | E7: =MAX(0,MIN(D7,Own_Labor_Hours)-MIN((D7-C7),Own_Labor_Hours))*Farmer_Implied_Wage+(C7-MAX(0,MIN(D7,Own_Labor_Hours)-MIN((D7-C7),Own_Labor_Hours)))*Temp_Wage_Per_Hour+Tomato_Fertilizer_Per_Bed | F7: =Tomato_Price-E7 | G7: =SUM($F$5:F7) | H7: =AND(H6,F7>=0) | I7: =ROW()-4 | J7: =(I7*Carrot_Base_Labor_Hrs_Wk_Bed*Season_Weeks*(1+Carrot_Diminishing_Rate)^I7)-((I7-1)*Carrot_Base_Labor_Hrs_Wk_Bed*Season_Weeks*(1+Carrot_Diminishing_Rate)^(I7-1)) | K7: =SUM($J$5:J7) | L7: =MAX(0,MIN(K7,Own_Labor_Hours)-MIN((K7-J7),Own_Labor_Hours))*Farmer_Implied_Wage+(J7-MAX(0,MIN(K7,Own_Labor_Hours)-MIN((K7-J7),Own_Labor_Hours)))*Temp_Wage_Per_Hour+Carrot_Fertilizer_Per_Bed | M7: =Carrot_Price-L7 | N7: =SUM($M$5:M7) | O7: =AND(O6,M7>=0) | P7: =ROW()-4 | Q7: =(P7*Mesclun_Base_Labor_Hrs_Wk_Bed*Season_Weeks*(1+Mesclun_Diminishing_Rate)^P7)-((P7-1)*Mesclun_Base_Labor_Hrs_Wk_Bed*Season_Weeks*(1+Mesclun_Diminishing_Rate)^(P7-1)) | R7: =SUM($Q$5:Q7) | S7: =MAX(0,MIN(R7,Own_Labor_Hours)-MIN((R7-Q7),Own_Labor_Hours))*Farmer_Implied_Wage+(Q7-MAX(0,MIN(R7,Own_Labor_Hours)-MIN((R7-Q7),Own_Labor_Hours)))*Temp_Wage_Per_Hour+Mesclun_Fertilizer_Per_Bed | T7: =Mesclun_Price-S7 | U7: =SUM($T$5:T7) | V7: =AND(V6,T7>=0)
B8: =ROW()-4 | C8: =(B8*Tomato_Base_Labor_Hrs_Wk_Bed*Season_Weeks*(1+Tomato_Diminishing_Rate)^B8)-((B8-1)*Tomato_Base_Labor_Hrs_Wk_Bed*Season_Weeks*(1+Tomato_Diminishing_Rate)^(B8-1)) | D8: =SUM($C$5:C8) | E8: =MAX(0,MIN(D8,Own_Labor_Hours)-MIN((D8-C8),Own_Labor_Hours))*Farmer_Implied_Wage+(C8-MAX(0,MIN(D8,Own_Labor_Hours)-MIN((D8-C8),Own_Labor_Hours)))*Temp_Wage_Per_Hour+Tomato_Fertilizer_Per_Bed | F8: =Tomato_Price-E8 | G8: =SUM($F$5:F8) | H8: =AND(H7,F8>=0) | I8: =ROW()-4 | J8: =(I8*Carrot_Base_Labor_Hrs_Wk_Bed*Season_Weeks*(1+Carrot_Diminishing_Rate)^I8)-((I8-1)*Carrot_Base_Labor_Hrs_Wk_Bed*Season_Weeks*(1+Carrot_Diminishing_Rate)^(I8-1)) | K8: =SUM($J$5:J8) | L8: =MAX(0,MIN(K8,Own_Labor_Hours)-MIN((K8-J8),Own_Labor_Hours))*Farmer_Implied_Wage+(J8-MAX(0,MIN(K8,Own_Labor_Hours)-MIN((K8-J8),Own_Labor_Hours)))*Temp_Wage_Per_Hour+Carrot_Fertilizer_Per_Bed | M8: =Carrot_Price-L8 | N8: =SUM($M$5:M8) | O8: =AND(O7,M8>=0) | P8: =ROW()-4 | Q8: =(P8*Mesclun_Base_Labor_Hrs_Wk_Bed*Season_Weeks*(1+Mesclun_Diminishing_Rate)^P8)-((P8-1)*Mesclun_Base_Labor_Hrs_Wk_Bed*Season_Weeks*(1+Mesclun_Diminishing_Rate)^(P8-1)) | R8: =SUM($Q$5:Q8) | S8: =MAX(0,MIN(R8,Own_Labor_Hours)-MIN((R8-Q8),Own_Labor_Hours))*Farmer_Implied_Wage+(Q8-MAX(0,MIN(R8,Own_Labor_Hours)-MIN((R8-Q8),Own_Labor_Hours)))*Temp_Wage_Per_Hour+Mesclun_Fertilizer_Per_Bed | T8: =Mesclun_Price-S8 | U8: =SUM($T$5:T8) | V8: =AND(V7,T8>=0)
B9: =ROW()-4 | C9: =(B9*Tomato_Base_Labor_Hrs_Wk_Bed*Season_Weeks*(1+Tomato_Diminishing_Rate)^B9)-((B9-1)*Tomato_Base_Labor_Hrs_Wk_Bed*Season_Weeks*(1+Tomato_Diminishing_Rate)^(B9-1)) | D9: =SUM($C$5:C9) | E9: =MAX(0,MIN(D9,Own_Labor_Hours)-MIN((D9-C9),Own_Labor_Hours))*Farmer_Implied_Wage+(C9-MAX(0,MIN(D9,Own_Labor_Hours)-MIN((D9-C9),Own_Labor_Hours)))*Temp_Wage_Per_Hour+Tomato_Fertilizer_Per_Bed | F9: =Tomato_Price-E9 | G9: =SUM($F$5:F9) | H9: =AND(H8,F9>=0) | I9: =ROW()-4 | J9: =(I9*Carrot_Base_Labor_Hrs_Wk_Bed*Season_Weeks*(1+Carrot_Diminishing_Rate)^I9)-((I9-1)*Carrot_Base_Labor_Hrs_Wk_Bed*Season_Weeks*(1+Carrot_Diminishing_Rate)^(I9-1)) | K9: =SUM($J$5:J9) | L9: =MAX(0,MIN(K9,Own_Labor_Hours)-MIN((K9-J9),Own_Labor_Hours))*Farmer_Implied_Wage+(J9-MAX(0,MIN(K9,Own_Labor_Hours)-MIN((K9-J9),Own_Labor_Hours)))*Temp_Wage_Per_Hour+Carrot_Fertilizer_Per_Bed | M9: =Carrot_Price-L9 | N9: =SUM($M$5:M9) | O9: =AND(O8,M9>=0) | P9: =ROW()-4 | Q9: =(P9*Mesclun_Base_Labor_Hrs_Wk_Bed*Season_Weeks*(1+Mesclun_Diminishing_Rate)^P9)-((P9-1)*Mesclun_Base_Labor_Hrs_Wk_Bed*Season_Weeks*(1+Mesclun_Diminishing_Rate)^(P9-1)) | R9: =SUM($Q$5:Q9) | S9: =MAX(0,MIN(R9,Own_Labor_Hours)-MIN((R9-Q9),Own_Labor_Hours))*Farmer_Implied_Wage+(Q9-MAX(0,MIN(R9,Own_Labor_Hours)-MIN((R9-Q9),Own_Labor_Hours)))*Temp_Wage_Per_Hour+Mesclun_Fertilizer_Per_Bed | T9: =Mesclun_Price-S9 | U9: =SUM($T$5:T9) | V9: =AND(V8,T9>=0)
B10: =ROW()-4 | C10: =(B10*Tomato_Base_Labor_Hrs_Wk_Bed*Season_Weeks*(1+Tomato_Diminishing_Rate)^B10)-((B10-1)*Tomato_Base_Labor_Hrs_Wk_Bed*Season_Weeks*(1+Tomato_Diminishing_Rate)^(B10-1)) | D10: =SUM($C$5:C10) | E10: =MAX(0,MIN(D10,Own_Labor_Hours)-MIN((D10-C10),Own_Labor_Hours))*Farmer_Implied_Wage+(C10-MAX(0,MIN(D10,Own_Labor_Hours)-MIN((D10-C10),Own_Labor_Hours)))*Temp_Wage_Per_Hour+Tomato_Fertilizer_Per_Bed | F10: =Tomato_Price-E10 | G10: =SUM($F$5:F10) | H10: =AND(H9,F10>=0) | I10: =ROW()-4 | J10: =(I10*Carrot_Base_Labor_Hrs_Wk_Bed*Season_Weeks*(1+Carrot_Diminishing_Rate)^I10)-((I10-1)*Carrot_Base_Labor_Hrs_Wk_Bed*Season_Weeks*(1+Carrot_Diminishing_Rate)^(I10-1)) | K10: =SUM($J$5:J10) | L10: =MAX(0,MIN(K10,Own_Labor_Hours)-MIN((K10-J10),Own_Labor_Hours))*Farmer_Implied_Wage+(J10-MAX(0,MIN(K10,Own_Labor_Hours)-MIN((K10-J10),Own_Labor_Hours)))*Temp_Wage_Per_Hour+Carrot_Fertilizer_Per_Bed | M10: =Carrot_Price-L10 | N10: =SUM($M$5:M10) | O10: =AND(O9,M10>=0) | P10: =ROW()-4 | Q10: =(P10*Mesclun_Base_Labor_Hrs_Wk_Bed*Season_Weeks*(1+Mesclun_Diminishing_Rate)^P10)-((P10-1)*Mesclun_Base_Labor_Hrs_Wk_Bed*Season_Weeks*(1+Mesclun_Diminishing_Rate)^(P10-1)) | R10: =SUM($Q$5:Q10) | S10: =MAX(0,MIN(R10,Own_Labor_Hours)-MIN((R10-Q10),Own_Labor_Hours))*Farmer_Implied_Wage+(Q10-MAX(0,MIN(R10,Own_Labor_Hours)-MIN((R10-Q10),Own_Labor_Hours)))*Temp_Wage_Per_Hour+Mesclun_Fertilizer_Per_Bed | T10: =Mesclun_Price-S10 | U10: =SUM($T$5:T10) | V10: =AND(V9,T10>=0)
B11: =ROW()-4 | C11: =(B11*Tomato_Base_Labor_Hrs_Wk_Bed*Season_Weeks*(1+Tomato_Diminishing_Rate)^B11)-((B11-1)*Tomato_Base_Labor_Hrs_Wk_Bed*Season_Weeks*(1+Tomato_Diminishing_Rate)^(B11-1)) | D11: =SUM($C$5:C11) | E11: =MAX(0,MIN(D11,Own_Labor_Hours)-MIN((D11-C11),Own_Labor_Hours))*Farmer_Implied_Wage+(C11-MAX(0,MIN(D11,Own_Labor_Hours)-MIN((D11-C11),Own_Labor_Hours)))*Temp_Wage_Per_Hour+Tomato_Fertilizer_Per_Bed | F11: =Tomato_Price-E11 | G11: =SUM($F$5:F11) | H11: =AND(H10,F11>=0) | I11: =ROW()-4 | J11: =(I11*Carrot_Base_Labor_Hrs_Wk_Bed*Season_Weeks*(1+Carrot_Diminishing_Rate)^I11)-((I11-1)*Carrot_Base_Labor_Hrs_Wk_Bed*Season_Weeks*(1+Carrot_Diminishing_Rate)^(I11-1)) | K11: =SUM($J$5:J11) | L11: =MAX(0,MIN(K11,Own_Labor_Hours)-MIN((K11-J11),Own_Labor_Hours))*Farmer_Implied_Wage+(J11-MAX(0,MIN(K11,Own_Labor_Hours)-MIN((K11-J11),Own_Labor_Hours)))*Temp_Wage_Per_Hour+Carrot_Fertilizer_Per_Bed | M11: =Carrot_Price-L11 | N11: =SUM($M$5:M11) | O11: =AND(O10,M11>=0) | P11: =ROW()-4 | Q11: =(P11*Mesclun_Base_Labor_Hrs_Wk_Bed*Season_Weeks*(1+Mesclun_Diminishing_Rate)^P11)-((P11-1)*Mesclun_Base_Labor_Hrs_Wk_Bed*Season_Weeks*(1+Mesclun_Diminishing_Rate)^(P11-1)) | R11: =SUM($Q$5:Q11) | S11: =MAX(0,MIN(R11,Own_Labor_Hours)-MIN((R11-Q11),Own_Labor_Hours))*Farmer_Implied_Wage+(Q11-MAX(0,MIN(R11,Own_Labor_Hours)-MIN((R11-Q11),Own_Labor_Hours)))*Temp_Wage_Per_Hour+Mesclun_Fertilizer_Per_Bed | T11: =Mesclun_Price-S11 | U11: =SUM($T$5:T11) | V11: =AND(V10,T11>=0)
B12: =ROW()-4 | C12: =(B12*Tomato_Base_Labor_Hrs_Wk_Bed*Season_Weeks*(1+Tomato_Diminishing_Rate)^B12)-((B12-1)*Tomato_Base_Labor_Hrs_Wk_Bed*Season_Weeks*(1+Tomato_Diminishing_Rate)^(B12-1)) | D12: =SUM($C$5:C12) | E12: =MAX(0,MIN(D12,Own_Labor_Hours)-MIN((D12-C12),Own_Labor_Hours))*Farmer_Implied_Wage+(C12-MAX(0,MIN(D12,Own_Labor_Hours)-MIN((D12-C12),Own_Labor_Hours)))*Temp_Wage_Per_Hour+Tomato_Fertilizer_Per_Bed | F12: =Tomato_Price-E12 | G12: =SUM($F$5:F12) | H12: =AND(H11,F12>=0) | I12: =ROW()-4 | J12: =(I12*Carrot_Base_Labor_Hrs_Wk_Bed*Season_Weeks*(1+Carrot_Diminishing_Rate)^I12)-((I12-1)*Carrot_Base_Labor_Hrs_Wk_Bed*Season_Weeks*(1+Carrot_Diminishing_Rate)^(I12-1)) | K12: =SUM($J$5:J12) | L12: =MAX(0,MIN(K12,Own_Labor_Hours)-MIN((K12-J12),Own_Labor_Hours))*Farmer_Implied_Wage+(J12-MAX(0,MIN(K12,Own_Labor_Hours)-MIN((K12-J12),Own_Labor_Hours)))*Temp_Wage_Per_Hour+Carrot_Fertilizer_Per_Bed | M12: =Carrot_Price-L12 | N12: =SUM($M$5:M12) | O12: =AND(O11,M12>=0) | P12: =ROW()-4 | Q12: =(P12*Mesclun_Base_Labor_Hrs_Wk_Bed*Season_Weeks*(1+Mesclun_Diminishing_Rate)^P12)-((P12-1)*Mesclun_Base_Labor_Hrs_Wk_Bed*Season_Weeks*(1+Mesclun_Diminishing_Rate)^(P12-1)) | R12: =SUM($Q$5:Q12) | S12: =MAX(0,MIN(R12,Own_Labor_Hours)-MIN((R12-Q12),Own_Labor_Hours))*Farmer_Implied_Wage+(Q12-MAX(0,MIN(R12,Own_Labor_Hours)-MIN((R12-Q12),Own_Labor_Hours)))*Temp_Wage_Per_Hour+Mesclun_Fertilizer_Per_Bed | T12: =Mesclun_Price-S12 | U12: =SUM($T$5:T12) | V12: =AND(V11,T12>=0)
B13: =ROW()-4 | C13: =(B13*Tomato_Base_Labor_Hrs_Wk_Bed*Season_Weeks*(1+Tomato_Diminishing_Rate)^B13)-((B13-1)*Tomato_Base_Labor_Hrs_Wk_Bed*Season_Weeks*(1+Tomato_Diminishing_Rate)^(B13-1)) | D13: =SUM($C$5:C13) | E13: =MAX(0,MIN(D13,Own_Labor_Hours)-MIN((D13-C13),Own_Labor_Hours))*Farmer_Implied_Wage+(C13-MAX(0,MIN(D13,Own_Labor_Hours)-MIN((D13-C13),Own_Labor_Hours)))*Temp_Wage_Per_Hour+Tomato_Fertilizer_Per_Bed | F13: =Tomato_Price-E13 | G13: =SUM($F$5:F13) | H13: =AND(H12,F13>=0) | I13: =ROW()-4 | J13: =(I13*Carrot_Base_Labor_Hrs_Wk_Bed*Season_Weeks*(1+Carrot_Diminishing_Rate)^I13)-((I13-1)*Carrot_Base_Labor_Hrs_Wk_Bed*Season_Weeks*(1+Carrot_Diminishing_Rate)^(I13-1)) | K13: =SUM($J$5:J13) | L13: =MAX(0,MIN(K13,Own_Labor_Hours)-MIN((K13-J13),Own_Labor_Hours))*Farmer_Implied_Wage+(J13-MAX(0,MIN(K13,Own_Labor_Hours)-MIN((K13-J13),Own_Labor_Hours)))*Temp_Wage_Per_Hour+Carrot_Fertilizer_Per_Bed | M13: =Carrot_Price-L13 | N13: =SUM($M$5:M13) | O13: =AND(O12,M13>=0) | P13: =ROW()-4 | Q13: =(P13*Mesclun_Base_Labor_Hrs_Wk_Bed*Season_Weeks*(1+Mesclun_Diminishing_Rate)^P13)-((P13-1)*Mesclun_Base_Labor_Hrs_Wk_Bed*Season_Weeks*(1+Mesclun_Diminishing_Rate)^(P13-1)) | R13: =SUM($Q$5:Q13) | S13: =MAX(0,MIN(R13,Own_Labor_Hours)-MIN((R13-Q13),Own_Labor_Hours))*Farmer_Implied_Wage+(Q13-MAX(0,MIN(R13,Own_Labor_Hours)-MIN((R13-Q13),Own_Labor_Hours)))*Temp_Wage_Per_Hour+Mesclun_Fertilizer_Per_Bed | T13: =Mesclun_Price-S13 | U13: =SUM($T$5:T13) | V13: =AND(V12,T13>=0)
B14: =ROW()-4 | C14: =(B14*Tomato_Base_Labor_Hrs_Wk_Bed*Season_Weeks*(1+Tomato_Diminishing_Rate)^B14)-((B14-1)*Tomato_Base_Labor_Hrs_Wk_Bed*Season_Weeks*(1+Tomato_Diminishing_Rate)^(B14-1)) | D14: =SUM($C$5:C14) | E14: =MAX(0,MIN(D14,Own_Labor_Hours)-MIN((D14-C14),Own_Labor_Hours))*Farmer_Implied_Wage+(C14-MAX(0,MIN(D14,Own_Labor_Hours)-MIN((D14-C14),Own_Labor_Hours)))*Temp_Wage_Per_Hour+Tomato_Fertilizer_Per_Bed | F14: =Tomato_Price-E14 | G14: =SUM($F$5:F14) | H14: =AND(H13,F14>=0) | I14: =ROW()-4 | J14: =(I14*Carrot_Base_Labor_Hrs_Wk_Bed*Season_Weeks*(1+Carrot_Diminishing_Rate)^I14)-((I14-1)*Carrot_Base_Labor_Hrs_Wk_Bed*Season_Weeks*(1+Carrot_Diminishing_Rate)^(I14-1)) | K14: =SUM($J$5:J14) | L14: =MAX(0,MIN(K14,Own_Labor_Hours)-MIN((K14-J14),Own_Labor_Hours))*Farmer_Implied_Wage+(J14-MAX(0,MIN(K14,Own_Labor_Hours)-MIN((K14-J14),Own_Labor_Hours)))*Temp_Wage_Per_Hour+Carrot_Fertilizer_Per_Bed | M14: =Carrot_Price-L14 | N14: =SUM($M$5:M14) | O14: =AND(O13,M14>=0) | P14: =ROW()-4 | Q14: =(P14*Mesclun_Base_Labor_Hrs_Wk_Bed*Season_Weeks*(1+Mesclun_Diminishing_Rate)^P14)-((P14-1)*Mesclun_Base_Labor_Hrs_Wk_Bed*Season_Weeks*(1+Mesclun_Diminishing_Rate)^(P14-1)) | R14: =SUM($Q$5:Q14) | S14: =MAX(0,MIN(R14,Own_Labor_Hours)-MIN((R14-Q14),Own_Labor_Hours))*Farmer_Implied_Wage+(Q14-MAX(0,MIN(R14,Own_Labor_Hours)-MIN((R14-Q14),Own_Labor_Hours)))*Temp_Wage_Per_Hour+Mesclun_Fertilizer_Per_Bed | T14: =Mesclun_Price-S14 | U14: =SUM($T$5:T14) | V14: =AND(V13,T14>=0)
B15: =ROW()-4 | C15: =(B15*Tomato_Base_Labor_Hrs_Wk_Bed*Season_Weeks*(1+Tomato_Diminishing_Rate)^B15)-((B15-1)*Tomato_Base_Labor_Hrs_Wk_Bed*Season_Weeks*(1+Tomato_Diminishing_Rate)^(B15-1)) | D15: =SUM($C$5:C15) | E15: =MAX(0,MIN(D15,Own_Labor_Hours)-MIN((D15-C15),Own_Labor_Hours))*Farmer_Implied_Wage+(C15-MAX(0,MIN(D15,Own_Labor_Hours)-MIN((D15-C15),Own_Labor_Hours)))*Temp_Wage_Per_Hour+Tomato_Fertilizer_Per_Bed | F15: =Tomato_Price-E15 | G15: =SUM($F$5:F15) | H15: =AND(H14,F15>=0) | I15: =ROW()-4 | J15: =(I15*Carrot_Base_Labor_Hrs_Wk_Bed*Season_Weeks*(1+Carrot_Diminishing_Rate)^I15)-((I15-1)*Carrot_Base_Labor_Hrs_Wk_Bed*Season_Weeks*(1+Carrot_Diminishing_Rate)^(I15-1)) | K15: =SUM($J$5:J15) | L15: =MAX(0,MIN(K15,Own_Labor_Hours)-MIN((K15-J15),Own_Labor_Hours))*Farmer_Implied_Wage+(J15-MAX(0,MIN(K15,Own_Labor_Hours)-MIN((K15-J15),Own_Labor_Hours)))*Temp_Wage_Per_Hour+Carrot_Fertilizer_Per_Bed | M15: =Carrot_Price-L15 | N15: =SUM($M$5:M15) | O15: =AND(O14,M15>=0) | P15: =ROW()-4 | Q15: =(P15*Mesclun_Base_Labor_Hrs_Wk_Bed*Season_Weeks*(1+Mesclun_Diminishing_Rate)^P15)-((P15-1)*Mesclun_Base_Labor_Hrs_Wk_Bed*Season_Weeks*(1+Mesclun_Diminishing_Rate)^(P15-1)) | R15: =SUM($Q$5:Q15) | S15: =MAX(0,MIN(R15,Own_Labor_Hours)-MIN((R15-Q15),Own_Labor_Hours))*Farmer_Implied_Wage+(Q15-MAX(0,MIN(R15,Own_Labor_Hours)-MIN((R15-Q15),Own_Labor_Hours)))*Temp_Wage_Per_Hour+Mesclun_Fertilizer_Per_Bed | T15: =Mesclun_Price-S15 | U15: =SUM($T$5:T15) | V15: =AND(V14,T15>=0)
B16: =ROW()-4 | C16: =(B16*Tomato_Base_Labor_Hrs_Wk_Bed*Season_Weeks*(1+Tomato_Diminishing_Rate)^B16)-((B16-1)*Tomato_Base_Labor_Hrs_Wk_Bed*Season_Weeks*(1+Tomato_Diminishing_Rate)^(B16-1)) | D16: =SUM($C$5:C16) | E16: =MAX(0,MIN(D16,Own_Labor_Hours)-MIN((D16-C16),Own_Labor_Hours))*Farmer_Implied_Wage+(C16-MAX(0,MIN(D16,Own_Labor_Hours)-MIN((D16-C16),Own_Labor_Hours)))*Temp_Wage_Per_Hour+Tomato_Fertilizer_Per_Bed | F16: =Tomato_Price-E16 | G16: =SUM($F$5:F16) | H16: =AND(H15,F16>=0) | I16: =ROW()-4 | J16: =(I16*Carrot_Base_Labor_Hrs_Wk_Bed*Season_Weeks*(1+Carrot_Diminishing_Rate)^I16)-((I16-1)*Carrot_Base_Labor_Hrs_Wk_Bed*Season_Weeks*(1+Carrot_Diminishing_Rate)^(I16-1)) | K16: =SUM($J$5:J16) | L16: =MAX(0,MIN(K16,Own_Labor_Hours)-MIN((K16-J16),Own_Labor_Hours))*Farmer_Implied_Wage+(J16-MAX(0,MIN(K16,Own_Labor_Hours)-MIN((K16-J16),Own_Labor_Hours)))*Temp_Wage_Per_Hour+Carrot_Fertilizer_Per_Bed | M16: =Carrot_Price-L16 | N16: =SUM($M$5:M16) | O16: =AND(O15,M16>=0) | P16: =ROW()-4 | Q16: =(P16*Mesclun_Base_Labor_Hrs_Wk_Bed*Season_Weeks*(1+Mesclun_Diminishing_Rate)^P16)-((P16-1)*Mesclun_Base_Labor_Hrs_Wk_Bed*Season_Weeks*(1+Mesclun_Diminishing_Rate)^(P16-1)) | R16: =SUM($Q$5:Q16) | S16: =MAX(0,MIN(R16,Own_Labor_Hours)-MIN((R16-Q16),Own_Labor_Hours))*Farmer_Implied_Wage+(Q16-MAX(0,MIN(R16,Own_Labor_Hours)-MIN((R16-Q16),Own_Labor_Hours)))*Temp_Wage_Per_Hour+Mesclun_Fertilizer_Per_Bed | T16: =Mesclun_Price-S16 | U16: =SUM($T$5:T16) | V16: =AND(V15,T16>=0)
B17: =ROW()-4 | C17: =(B17*Tomato_Base_Labor_Hrs_Wk_Bed*Season_Weeks*(1+Tomato_Diminishing_Rate)^B17)-((B17-1)*Tomato_Base_Labor_Hrs_Wk_Bed*Season_Weeks*(1+Tomato_Diminishing_Rate)^(B17-1)) | D17: =SUM($C$5:C17) | E17: =MAX(0,MIN(D17,Own_Labor_Hours)-MIN((D17-C17),Own_Labor_Hours))*Farmer_Implied_Wage+(C17-MAX(0,MIN(D17,Own_Labor_Hours)-MIN((D17-C17),Own_Labor_Hours)))*Temp_Wage_Per_Hour+Tomato_Fertilizer_Per_Bed | F17: =Tomato_Price-E17 | G17: =SUM($F$5:F17) | H17: =AND(H16,F17>=0) | I17: =ROW()-4 | J17: =(I17*Carrot_Base_Labor_Hrs_Wk_Bed*Season_Weeks*(1+Carrot_Diminishing_Rate)^I17)-((I17-1)*Carrot_Base_Labor_Hrs_Wk_Bed*Season_Weeks*(1+Carrot_Diminishing_Rate)^(I17-1)) | K17: =SUM($J$5:J17) | L17: =MAX(0,MIN(K17,Own_Labor_Hours)-MIN((K17-J17),Own_Labor_Hours))*Farmer_Implied_Wage+(J17-MAX(0,MIN(K17,Own_Labor_Hours)-MIN((K17-J17),Own_Labor_Hours)))*Temp_Wage_Per_Hour+Carrot_Fertilizer_Per_Bed | M17: =Carrot_Price-L17 | N17: =SUM($M$5:M17) | O17: =AND(O16,M17>=0) | P17: =ROW()-4 | Q17: =(P17*Mesclun_Base_Labor_Hrs_Wk_Bed*Season_Weeks*(1+Mesclun_Diminishing_Rate)^P17)-((P17-1)*Mesclun_Base_Labor_Hrs_Wk_Bed*Season_Weeks*(1+Mesclun_Diminishing_Rate)^(P17-1)) | R17: =SUM($Q$5:Q17) | S17: =MAX(0,MIN(R17,Own_Labor_Hours)-MIN((R17-Q17),Own_Labor_Hours))*Farmer_Implied_Wage+(Q17-MAX(0,MIN(R17,Own_Labor_Hours)-MIN((R17-Q17),Own_Labor_Hours)))*Temp_Wage_Per_Hour+Mesclun_Fertilizer_Per_Bed | T17: =Mesclun_Price-S17 | U17: =SUM($T$5:T17) | V17: =AND(V16,T17>=0)
... B24: =ROW()-4 | C24: =(B24*Tomato_Base_Labor_Hrs_Wk_Bed*Season_Weeks*(1+Tomato_Diminishing_Rate)^B24)-((B24-1)*Tomato_Base_Labor_Hrs_Wk_Bed*Season_Weeks*(1+Tomato_Diminishing_Rate)^(B24-1)) | D24: =SUM($C$5:C24) | E24: =MAX(0,MIN(D24,Own_Labor_Hours)-MIN((D24-C24),Own_Labor_Hours))*Farmer_Implied_Wage+(C24-MAX(0,MIN(D24,Own_Labor_Hours)-MIN((D24-C24),Own_Labor_Hours)))*Temp_Wage_Per_Hour+Tomato_Fertilizer_Per_Bed | F24: =Tomato_Price-E24 | G24: =SUM($F$5:F24) | H24: =AND(H23,F24>=0) | I24: =ROW()-4 | J24: =(I24*Carrot_Base_Labor_Hrs_Wk_Bed*Season_Weeks*(1+Carrot_Diminishing_Rate)^I24)-((I24-1)*Carrot_Base_Labor_Hrs_Wk_Bed*Season_Weeks*(1+Carrot_Diminishing_Rate)^(I24-1)) | K24: =SUM($J$5:J24) | L24: =MAX(0,MIN(K24,Own_Labor_Hours)-MIN((K24-J24),Own_Labor_Hours))*Farmer_Implied_Wage+(J24-MAX(0,MIN(K24,Own_Labor_Hours)-MIN((K24-J24),Own_Labor_Hours)))*Temp_Wage_Per_Hour+Carrot_Fertilizer_Per_Bed | M24: =Carrot_Price-L24 | N24: =SUM($M$5:M24) | O24: =AND(O23,M24>=0) | P24: =ROW()-4 | Q24: =(P24*Mesclun_Base_Labor_Hrs_Wk_Bed*Season_Weeks*(1+Mesclun_Diminishing_Rate)^P24)-((P24-1)*Mesclun_Base_Labor_Hrs_Wk_Bed*Season_Weeks*(1+Mesclun_Diminishing_Rate)^(P24-1)) | R24: =SUM($Q$5:Q24) | S24: =MAX(0,MIN(R24,Own_Labor_Hours)-MIN((R24-Q24),Own_Labor_Hours))*Farmer_Implied_Wage+(Q24-MAX(0,MIN(R24,Own_Labor_Hours)-MIN((R24-Q24),Own_Labor_Hours)))*Temp_Wage_Per_Hour+Mesclun_Fertilizer_Per_Bed | T24: =Mesclun_Price-S24 | U24: =SUM($T$5:T24) | V24: =AND(V23,T24>=0)
P25: =ROW()-4 | Q25: =(P25*Mesclun_Base_Labor_Hrs_Wk_Bed*Season_Weeks*(1+Mesclun_Diminishing_Rate)^P25)-((P25-1)*Mesclun_Base_Labor_Hrs_Wk_Bed*Season_Weeks*(1+Mesclun_Diminishing_Rate)^(P25-1)) | R25: =SUM($Q$5:Q25) | S25: =MAX(0,MIN(R25,Own_Labor_Hours)-MIN((R25-Q25),Own_Labor_Hours))*Farmer_Implied_Wage+(Q25-MAX(0,MIN(R25,Own_Labor_Hours)-MIN((R25-Q25),Own_Labor_Hours)))*Temp_Wage_Per_Hour+Mesclun_Fertilizer_Per_Bed | T25: =Mesclun_Price-S25 | U25: =SUM($T$5:T25) | V25: =AND(V24,T25>=0)
B26: Standalone last-profitable bed (first crossover, per the lab's own definition): | F26: =SUMPRODUCT((H5:H24)*1) | I26: Standalone last-profitable bed (first crossover, per the lab's own definition): | M26: =SUMPRODUCT((O5:O24)*1) | P26: =ROW()-4 | Q26: =(P26*Mesclun_Base_Labor_Hrs_Wk_Bed*Season_Weeks*(1+Mesclun_Diminishing_Rate)^P26)-((P26-1)*Mesclun_Base_Labor_Hrs_Wk_Bed*Season_Weeks*(1+Mesclun_Diminishing_Rate)^(P26-1)) | R26: =SUM($Q$5:Q26) | S26: =MAX(0,MIN(R26,Own_Labor_Hours)-MIN((R26-Q26),Own_Labor_Hours))*Farmer_Implied_Wage+(Q26-MAX(0,MIN(R26,Own_Labor_Hours)-MIN((R26-Q26),Own_Labor_Hours)))*Temp_Wage_Per_Hour+Mesclun_Fertilizer_Per_Bed | T26: =Mesclun_Price-S26 | U26: =SUM($T$5:T26) | V26: =AND(V25,T26>=0)
P27: =ROW()-4 | Q27: =(P27*Mesclun_Base_Labor_Hrs_Wk_Bed*Season_Weeks*(1+Mesclun_Diminishing_Rate)^P27)-((P27-1)*Mesclun_Base_Labor_Hrs_Wk_Bed*Season_Weeks*(1+Mesclun_Diminishing_Rate)^(P27-1)) | R27: =SUM($Q$5:Q27) | S27: =MAX(0,MIN(R27,Own_Labor_Hours)-MIN((R27-Q27),Own_Labor_Hours))*Farmer_Implied_Wage+(Q27-MAX(0,MIN(R27,Own_Labor_Hours)-MIN((R27-Q27),Own_Labor_Hours)))*Temp_Wage_Per_Hour+Mesclun_Fertilizer_Per_Bed | T27: =Mesclun_Price-S27 | U27: =SUM($T$5:T27) | V27: =AND(V26,T27>=0)
P28: =ROW()-4 | Q28: =(P28*Mesclun_Base_Labor_Hrs_Wk_Bed*Season_Weeks*(1+Mesclun_Diminishing_Rate)^P28)-((P28-1)*Mesclun_Base_Labor_Hrs_Wk_Bed*Season_Weeks*(1+Mesclun_Diminishing_Rate)^(P28-1)) | R28: =SUM($Q$5:Q28) | S28: =MAX(0,MIN(R28,Own_Labor_Hours)-MIN((R28-Q28),Own_Labor_Hours))*Farmer_Implied_Wage+(Q28-MAX(0,MIN(R28,Own_Labor_Hours)-MIN((R28-Q28),Own_Labor_Hours)))*Temp_Wage_Per_Hour+Mesclun_Fertilizer_Per_Bed | T28: =Mesclun_Price-S28 | U28: =SUM($T$5:T28) | V28: =AND(V27,T28>=0)
P29: =ROW()-4 | Q29: =(P29*Mesclun_Base_Labor_Hrs_Wk_Bed*Season_Weeks*(1+Mesclun_Diminishing_Rate)^P29)-((P29-1)*Mesclun_Base_Labor_Hrs_Wk_Bed*Season_Weeks*(1+Mesclun_Diminishing_Rate)^(P29-1)) | R29: =SUM($Q$5:Q29) | S29: =MAX(0,MIN(R29,Own_Labor_Hours)-MIN((R29-Q29),Own_Labor_Hours))*Farmer_Implied_Wage+(Q29-MAX(0,MIN(R29,Own_Labor_Hours)-MIN((R29-Q29),Own_Labor_Hours)))*Temp_Wage_Per_Hour+Mesclun_Fertilizer_Per_Bed | T29: =Mesclun_Price-S29 | U29: =SUM($T$5:T29) | V29: =AND(V28,T29>=0)
P30: =ROW()-4 | Q30: =(P30*Mesclun_Base_Labor_Hrs_Wk_Bed*Season_Weeks*(1+Mesclun_Diminishing_Rate)^P30)-((P30-1)*Mesclun_Base_Labor_Hrs_Wk_Bed*Season_Weeks*(1+Mesclun_Diminishing_Rate)^(P30-1)) | R30: =SUM($Q$5:Q30) | S30: =MAX(0,MIN(R30,Own_Labor_Hours)-MIN((R30-Q30),Own_Labor_Hours))*Farmer_Implied_Wage+(Q30-MAX(0,MIN(R30,Own_Labor_Hours)-MIN((R30-Q30),Own_Labor_Hours)))*Temp_Wage_Per_Hour+Mesclun_Fertilizer_Per_Bed | T30: =Mesclun_Price-S30 | U30: =SUM($T$5:T30) | V30: =AND(V29,T30>=0)
P31: =ROW()-4 | Q31: =(P31*Mesclun_Base_Labor_Hrs_Wk_Bed*Season_Weeks*(1+Mesclun_Diminishing_Rate)^P31)-((P31-1)*Mesclun_Base_Labor_Hrs_Wk_Bed*Season_Weeks*(1+Mesclun_Diminishing_Rate)^(P31-1)) | R31: =SUM($Q$5:Q31) | S31: =MAX(0,MIN(R31,Own_Labor_Hours)-MIN((R31-Q31),Own_Labor_Hours))*Farmer_Implied_Wage+(Q31-MAX(0,MIN(R31,Own_Labor_Hours)-MIN((R31-Q31),Own_Labor_Hours)))*Temp_Wage_Per_Hour+Mesclun_Fertilizer_Per_Bed | T31: =Mesclun_Price-S31 | U31: =SUM($T$5:T31) | V31: =AND(V30,T31>=0)
P32: =ROW()-4 | Q32: =(P32*Mesclun_Base_Labor_Hrs_Wk_Bed*Season_Weeks*(1+Mesclun_Diminishing_Rate)^P32)-((P32-1)*Mesclun_Base_Labor_Hrs_Wk_Bed*Season_Weeks*(1+Mesclun_Diminishing_Rate)^(P32-1)) | R32: =SUM($Q$5:Q32) | S32: =MAX(0,MIN(R32,Own_Labor_Hours)-MIN((R32-Q32),Own_Labor_Hours))*Farmer_Implied_Wage+(Q32-MAX(0,MIN(R32,Own_Labor_Hours)-MIN((R32-Q32),Own_Labor_Hours)))*Temp_Wage_Per_Hour+Mesclun_Fertilizer_Per_Bed | T32: =Mesclun_Price-S32 | U32: =SUM($T$5:T32) | V32: =AND(V31,T32>=0)
P33: =ROW()-4 | Q33: =(P33*Mesclun_Base_Labor_Hrs_Wk_Bed*Season_Weeks*(1+Mesclun_Diminishing_Rate)^P33)-((P33-1)*Mesclun_Base_Labor_Hrs_Wk_Bed*Season_Weeks*(1+Mesclun_Diminishing_Rate)^(P33-1)) | R33: =SUM($Q$5:Q33) | S33: =MAX(0,MIN(R33,Own_Labor_Hours)-MIN((R33-Q33),Own_Labor_Hours))*Farmer_Implied_Wage+(Q33-MAX(0,MIN(R33,Own_Labor_Hours)-MIN((R33-Q33),Own_Labor_Hours)))*Temp_Wage_Per_Hour+Mesclun_Fertilizer_Per_Bed | T33: =Mesclun_Price-S33 | U33: =SUM($T$5:T33) | V33: =AND(V32,T33>=0)
P34: =ROW()-4 | Q34: =(P34*Mesclun_Base_Labor_Hrs_Wk_Bed*Season_Weeks*(1+Mesclun_Diminishing_Rate)^P34)-((P34-1)*Mesclun_Base_Labor_Hrs_Wk_Bed*Season_Weeks*(1+Mesclun_Diminishing_Rate)^(P34-1)) | R34: =SUM($Q$5:Q34) | S34: =MAX(0,MIN(R34,Own_Labor_Hours)-MIN((R34-Q34),Own_Labor_Hours))*Farmer_Implied_Wage+(Q34-MAX(0,MIN(R34,Own_Labor_Hours)-MIN((R34-Q34),Own_Labor_Hours)))*Temp_Wage_Per_Hour+Mesclun_Fertilizer_Per_Bed | T34: =Mesclun_Price-S34 | U34: =SUM($T$5:T34) | V34: =AND(V33,T34>=0)
P36: Standalone last-profitable bed (first crossover, per the lab's own definition): | T36: =SUMPRODUCT((V5:V34)*1)
A38: Joint Allocation (decision cells live on the Solver tab)
A39: Beds — Tomato (from Solver) | E39: =Solver!$C$6
A40: Beds — Carrot (from Solver) | E40: =Solver!$C$7
A41: Beds — Mesclun (from Solver) | E41: =Solver!$C$8
A42: Temp workers hired (from Solver) | E42: =Solver!$C$9
A43: Cumulative labor hrs — Tomato @ chosen beds | E43: =IF($E$39=0,0,INDEX(D5:D24,$E$39))
A44: Cumulative labor hrs — Carrot @ chosen beds | E44: =IF($E$40=0,0,INDEX(K5:K24,$E$40))
A45: Cumulative labor hrs — Mesclun @ chosen beds | E45: =IF($E$41=0,0,INDEX(R5:R34,$E$41))
A46: Total labor hours needed | E46: =$E$43+$E$44+$E$45
A47: Temp workers needed (feasibility count, not a cost) | E47: =MIN(Temp_Worker_Max,IF($E$46<=Own_Labor_Hours,0,CEILING(($E$46-Own_Labor_Hours)/Temp_Worker_Hours,1)))
A48: Temp workers needed, unrounded (spec sec 6 check figure: ~3.16) | E48: =MAX(0,$E$46-Own_Labor_Hours)/Temp_Worker_Hours
...

Sheet Solver
A1: Solver — Decision Variables & Setup
A2: Values below are the validated optimum (exhaustive search + confirmed by the greedy walk on Calculations — see spec §6). Change them to explore other allocations.
A4: Decision Variables (Solver's "changing cells")
A6: Beds — Tomato | C6: 10
A7: Beds — Carrot | C7: 20
A8: Beds — Mesclun | C8: 30
A9: Temp workers hired | C9: 4
A11: Objective (Solver's "Set Objective" cell) — Maximize | C11: =Calculations!$E$53
A13: Constraints
A14: • Beds_Tomato <= Tomato_Bed_Cap
A15: • Beds_Carrot <= Carrot_Bed_Cap
A16: • Beds_Mesclun <= Mesclun_Bed_Cap
A17: • Beds_Tomato + Beds_Carrot + Beds_Mesclun <= Total_Beds
A18: • Total labor hours needed <= Own_Labor_Hours + Temp_Workers_Hired x Temp_Worker_Hours
A19: • Temp_Workers_Hired >= workers actually needed to cover the hours (no under-hiring)
A20: • 0 <= Temp_Workers_Hired <= Temp_Worker_Max, integer
A21: • All beds >= 0, integer
A23: Live constraint checks (linked from Calculations)
A24: Tomato beds <= cap | C24: =Calculations!$E$56
A25: Carrot beds <= cap | C25: =Calculations!$E$57
A26: Mesclun beds <= cap | C26: =Calculations!$E$58
A27: Total beds <= Total_Beds | C27: =Calculations!$E$59
A28: Temp workers valid (integer 0-4) | C28: =Calculations!$E$60
A29: Labor hours covered | C29: =Calculations!$E$61
A30: Not under-hired | C30: =Calculations!$E$62
A32: To re-run in Excel: Data tab > Solver > Set Objective = C11, To: Max, By Changing Variable Cells = C6:C9, Add the constraints above, Solving Method = Evolutionary or GRG Nonlinear (this cost model is smooth, no lumpy jump -- see spec sec 5), then Solve.

Sheet Notes
A1: Notes — Market Garden Bed Allocation Model (v1.5)
A3: What this model does
A4: Chooses how many of 64 beds to plant with tomatoes, carrots, and mesclun (one 36-week season, no mid-season replanting), and how many temp workers to hire, to maximize season profit. See capabilities/marginal-analysis/spec.md for the full spec, including section 6's validation log.
A6: Data sources
A7: - docs/briefs/perfect-competition-brief.md -- problem framing, fixed/chosen variables, assumptions, hypothesis.
A8: - Case materials (crop economics table) -- per-crop price, fertilizer $/bed, base labor hrs/wk/bed, diminishing-returns rate.
A9: - Farm Profit Lab (adamwstauffer.github.io/ai-lms/farmlab.html) -- validated the labor-wage tiering and confirmed the acceptance criteria (spec sec 6).
A11: Labor cost -- corrected in v1.3, wage inputs corrected again in v1.5
A12: The farmer's first 720 hours (shared across all three crops) are priced at Farmer_Implied_Wage -- the EXPENSIVE tier, not free. Hours beyond 720 drop to Temp_Wage_Per_Hour -- the CHEAP tier. There is no $0 tier and no separate Farmer_Salary fixed cost; her compensation is captured entirely through the per-hour Farmer_Implied_Wage charge.
A13: v1.5: Farmer_Implied_Wage and Temp_Wage_Per_Hour are formulas on Inputs (=Farmer_Season_Salary/2/Own_Labor_Hours = $34.7222.../hr, and =Temp_Worker_Flat_Cost/Temp_Worker_Hours = $17.3611.../hr), not the case materials' rounded, displayed values ($34.72 / $17.36). Entering the rounded values directly had moved season profit by several dollars -- small enough to hide inside a tolerance band, which is exactly why that tolerance was removed rather than kept (spec sec 6, v1.5 defect record).
A14: Open item: the brief states a $25,000-per-temp-worker lumpy hiring fee. The validated Farm Profit Lab's own P&L does not charge it -- Temp_Workers_Hired there is an informational feasibility count only. This model matches the validated (no-fee) version, since that's what reproduces the acceptance criteria. Worth confirming with Adam before treating as settled.
A16: Validated result
... A28: AI-assisted build -- logged in prompt-log.md per docs/standards/excel-formatting.md.
